
`Successfully built tlgfwk
ERROR: Exception:
Traceback (most recent call last):
  File "/usr/lib/python3/dist-packages/pip/_internal/cli/base_command.py", line 165, in exc_logging_wrapper
    status = run_func(*args)
  File "/usr/lib/python3/dist-packages/pip/_internal/cli/req_command.py", line 205, in wrapper
    return func(self, options, args)
  File "/usr/lib/python3/dist-packages/pip/_internal/commands/install.py", line 389, in run
    to_install = resolver.get_installation_order(requirement_set)
  File "/usr/lib/python3/dist-packages/pip/_internal/resolution/resolvelib/resolver.py", line 188, in get_installation_order
    weights = get_topological_weights(
  File "/usr/lib/python3/dist-packages/pip/_internal/resolution/resolvelib/resolver.py", line 276, in get_topological_weights
    assert len(weights) == expected_node_count`

---
